Workbook

Sheet Рассчеты (3)
A10: Протокол об испытаниях №0000.ВС/04.24 от 01.04.2024
A11: Анкеры механические для крепления в бетоне по ГОСТ 56731-2023
A13: Основание для проведения работ: | D13: СЧЕТ № 23305/14-11-25/2 от 14 ноября 2025 года
A14: Заказчик :
A15: Наименование объекта:
A16: Адрес объекта:
A17: Дата испытаний
A18: Вид испытаний: | D18: Испытание на вырыв
A19: Методика проведения испытаний: | D19: ГОСТ 56731-2023 Анкера механические для крепления в бетоне. Методы испытаний
A20: СТО-44416204-010-2010 «Крепления анкерные. Метод определения несущей способности по результатам натурных испытаний»
A21: Оборудование, инструменты: | D21: Измеритель адгезии ПСО-100МГ4АД зав. 2573, свидетельство о поверке «ВИК-НДТ», зав. №3581, свидетельство о калибровке № К0034-1001/24 действительно до 09.01.2025;
A22: № С-ГА/24-06-2025/444021486 действительно до 23.06.2027; Измеритель параметров микроклимата; Метеоскоп-М; "МЕТЕОСКОП-М"; Рег. № 32014-11 зав. № 615022, свидетельство о поверке №С-ДЮП/05-07-2024/353605602 действительно до 04.07.2026. Перфоратор DeWALT, рулетка, молоток.
A25: Описание и тип анкера, наименование изготовителя: | D25: Дюбель для теплоизоляции 10х180мм ИЗТ, с металлическим стержнем и термоголовкой - ООО "HILTI"
A26: Таблица 1
A27: Дата изготовления | B27: Место проведения | D27: Материал | E27: Метод сверления | F27: t, ℃ | G27: Глубина заделки, мм | H27: Расстояние между анкерами, мм | I27: Описание и тип анкера, наименование изготовителя: | N27: Случмежду
A28: 46059 | B28: Стена в/о 1-2/А-Б на отм. +1,050 | D28: Тяжелый бетон В25 | E28: Бурение | F28: 15 | G28: 36 | H28: 300 | I28: Анкер-Ш 10х180мм ИЗТ, с металлическим стержнем и термоголовкой - ООО "HILTI" | N28: =RANDBETWEEN(450,500)/10 -> 46.5
B30: № образца в серии
A31: № испытания | B31: Анкер-Ш 10х180мм | C31: Анкер-Ш 12х180мм
A32: 1 | B32: =RANDBETWEEN(450,500)/10 -> 49.6 | L32: 1 | M32: нарушение контакта анкера с бетоном | T32: Нагрузка
A33: 2 | B33: =RANDBETWEEN(450,500)/10 -> 46.4 | L33: 2 | M33: выкалывание бетона основания | T33: 1
A34: 3 | B34: =RANDBETWEEN(450,500)/10 -> 47.5 | L34: 3 | M34: разрушение анкера по стали | T34: 2
A35: 4 | B35: =RANDBETWEEN(450,500)/10 -> 45 | T35: 3
A36: 5 | B36: =RANDBETWEEN(450,500)/10 -> 49.6 | T36: 4
A37: 6 | B37: =RANDBETWEEN(450,500)/10 -> 46.2 | L37: 1 | M37: нарушение контакта анкера с бетоном | T37: 5
A38: 7 | B38: =RANDBETWEEN(450,500)/10 -> 45 | L38: 2 | M38: выкалывание бетона основания | T38: 6
A39: 8 | B39: =RANDBETWEEN(450,500)/10 -> 46.1 | L39: 3 | M39: разрушение анкера по стали | T39: 7
A40: 9 | B40: =RANDBETWEEN(450,500)/10 -> 48.6 | T40: 8
A41: 10 | B41: =RANDBETWEEN(450,500)/10 -> 48.3 | T41: 9
L42: 1 | M42: нарушение контакта анкера с бетоном | T42: 10
A43: Таблица 3 | T43: 15
A44: Среднее значение нагрузки N, кН: | C44: Среднеквадратическое отклонение S, кН: | E44: Коэф. вариации v, %: | F44: Коэф., К: | G44: Коэф. надёжности, m: | H44: Коэф. условий работы: | I44: Расч сопротивление | J44: Расчётное сопротивление с учетом коэффициента условий работы:
A45: 1 | C45: 2 | E45: 3 | F45: 4 | G45: 5 | H45: 6 | I45: 7
A46: =AVERAGE(B32:B41) -> 47.23 | C46: =1/A46*SQRT((B32-A46)^2/MAX(A32:A41)-1) -> #NUM!
A49: Коэффициент надёжности по материалу, m:
A50: Коэффициент условий работы:
A51: Расчётное сопротивление анкерного крепления:
A52: Расчётное сопротивление анкерного крепления с учетом коэффициента условий работы:
A53: Заведующий строительной лабораторией: | G53: _________________/Симоров А.Ю./
A55: Ответственные исполнители:
A57: Инженер: | G57: _________________/Симоров А.Ю./
...

Sheet -
A1: Для Методики
A2: ="ГОСТ 14098-2014 «Соединения сварные арматуры и закладных изделий железобетонных конструкций. Типы, конструкции и размеры», СП"&CHAR(160)&"13330.2012 «Несущие и ограждающие конструкции»." -> ГОСТ 14098-2014 «Соединения сварные арматуры и закладных изделий железобетонных конструкций. Типы, конструкции и размеры», СП 13330.2012 «Несущие и ограждающие конструкции».
A3: ="ГОСТ 23118-2019 «Конструкции строительные, стальные. Общие технические условия», СП"&CHAR(160)&"70.13330.2012 «Несущие и ограждающие конструкции»." -> ГОСТ 23118-2019 «Конструкции строительные, стальные. Общие технические условия», СП 70.13330.2012 «Несущие и ограждающие конструкции».
A4: ="ГОСТ 16037-80 «Соединения сварные стальных трубопроводов. Основные типы, конструктивные элементы и размеры», СП"&CHAR(160)&"74.13330.2023 «Тепловые сети»." -> ГОСТ 16037-80 «Соединения сварные стальных трубопроводов. Основные типы, конструктивные элементы и размеры», СП 74.13330.2023 «Тепловые сети».
A5: ="ГОСТ"&CHAR(160)&"16037-80 «Соединения сварные стальных трубопроводов. Основные типы, конструктивные элементы и размеры»." -> ГОСТ 16037-80 «Соединения сварные стальных трубопроводов. Основные типы, конструктивные элементы и размеры».
A6: ="ГОСТ"&CHAR(160)&"ISO 5817-2025 «Сварные соединения из стали, никеля, титана и их сплавов, полученные сваркой плавлением (исключая лучевые способы сварки). Уровни качества»." -> ГОСТ ISO 5817-2025 «Сварные соединения из стали, никеля, титана и их сплавов, полученные сваркой плавлением (исключая лучевые способы сварки). Уровни качества».
A7: ="СП"&CHAR(160)&"70.13330.2012 «Несущие и ограждающие конструкции»." -> СП 70.13330.2012 «Несущие и ограждающие конструкции».
A11: Способы сварки
A12: ="ГОСТ"&CHAR(160)&"14771-76 «Дуговая сварка в защитном газе. Соединения сварные. Основные типы, конструктивные элементы и размеры»." -> ГОСТ 14771-76 «Дуговая сварка в защитном газе. Соединения сварные. Основные типы, конструктивные элементы и размеры».
A13: ="ГОСТ"&CHAR(160)&"14776-79 «Дуговая сварка. Соединения точечные. Основные типы, конструктивные элементы и размеры»." -> ГОСТ 14776-79 «Дуговая сварка. Соединения точечные. Основные типы, конструктивные элементы и размеры».
A14: ="ГОСТ"&CHAR(160)&"5264-80 «Ручная дуговая сварка. Соединения сварные. Основные типы, конструктивные элементы и размеры»." -> ГОСТ 5264-80 «Ручная дуговая сварка. Соединения сварные. Основные типы, конструктивные элементы и размеры».

Sheet ВИК стр. 1
A1: Испытательная лаборатория ООО «ГЛАВЛАБГРУПП» ИНН/КПП 7724484743/772401001, ОГРН 1197746472802 Адрес: 115304, г. Москва, ул. Каспийская, дом 22, корпус 1, стр. 5, эт. 1, пом. 1, ком 5 и 5а Аттестат аккредитации №РОСС RU.31112.И002015 Срок действия до 24 июня 2026 года.
AA2: ЛЮКСЫ БРАТЬ ТУТ | AE2: 1 | AF2: При контроле недопустимых дефектов не выявлено.
AE3: 2 | AF3: В результате контроля выявлены дефекты.
AA4: На улице | AC4: 500 | AD4: 900
AC5: =RANDBETWEEN(AC4,AD4)*10 -> 5280 | AD5: лк
AA7: В помещении | AC7: 650 | AD7: 800
AC8: =RANDBETWEEN(AC7,AD7) -> 695
R9: УТВЕРЖДАЮ:
R10: Заведующий строительной лабораторией:
W11: Симоров А.Ю.
R12: (подпись)
R13: =TEXT($G$25,"[$-FC19]«ДД» ММММ ГГГГ \г.") -> «05» мая 2026 г.
A15: ="Протокол №"&MID(CELL("filename",A1),SEARCH("]",CELL("filename"))+1,255)&".ВС от "&TEXT($G$25,"ДД.ММ.ГГГГ")&"" -> Протокол №ВИК стр. 1.ВС от 05.05.2026
A16: Визуального и измерительного контроля по ГОСТ 17637-2024
A18: Заказчик : | G18: ООО «АТЛАНТ»
A19: Исполнитель: | G19: ООО «ГЛАВЛАБГРУПП»
A20: Наименование объекта: | G20: Квартал Издание. «Комплекс жилых домов переменной этажности со встроенно-пристроенными помещениями общественного назначения и подземной автостоянкой»
A22: Адрес объекта: | G22: г. Москва, внутригородское образование Нижегородское, шоссе Перовское, земельный участок с кадастровым номером 77:04:0002001:8601
A24: Вид контроля: | G24: Визуальный и измерительный контроль сварных соединений
A25: Дата проведения испытаний: | G25: 46147
A26: Методика испытаний: | G26: ГОСТ Р ИСО 17637-2024 Неразрушающий контроль сварных швов. Визуальный контроль сварных соединений, выполненых сваркой плавлением.
A28: Оценка качества: | G28: ГОСТ 23118-2019 «Конструкции строительные, стальные. Общие технические условия», СП 70.13330.2012 «Несущие и ограждающие конструкции».
A30: Способ сварки: | G30: ГОСТ 5264-80 «Ручная дуговая сварка. Соединения сварные. Основные типы, конструктивные элементы и размеры».
A32: Используемое оборудование: | G32: Комплект для визуального и измерительного контроля «ВИК-НДТ», зав. № 3581, сертификат о калибровке № К0068-0912/25, действителен до 08.12.2026; Люксметр еЛайт-мини, зав. № 01771-22, свидетельство о поверке № С-АЕЯ/17-10-2025/475404653, действительно до 16.10.2026
A36: Материал по проекту: | G36: Сталь С235
A37: Уровень освещенности, лк: | G37: =AC8 -> 695
A38: Исполнитель: | D38: контроль выполнил дефектоскопист II уровня____________________Паршутин Р.Ю. (удостоверение №0071-0278 (действительно до 09.2026)
A40: Заключение:
A41: ="При контроле недопустимых дефектов не выявлено. Тип шва Т1, С8, Н1 по "&LEFT(G28,FIND("-",G28)-1)&"." -> При контроле недопустимых дефектов не выявлено. Тип шва Т1, С8, Н1 по ГОСТ 23118.
A42: =_xlfn.CONCAT(Z42,G28) -> Сварные соединения распорной системы в/о 1-10-А-Д с отм. -5,650 до отм. +2,360, общей длиной 10,5 м.п. соответствуют требованиям ГОСТ 23118-2019 «Конструкции строительные, стальные. Общие технические условия», СП 70.13330.2012 «Несущие и ограждающие конструкции». | Z42: Сварные соединения распорной системы в/о 1-10-А-Д с отм. -5,650 до отм. +2,360, общей длиной 10,5 м.п. соответствуют требованиям
A45: Результаты визуального и измерительного контроля представлены в приложении А.
A46: Фотофиксация выявленных дефектов представлена в приложении Б.
A47: Ответственные исполнители:
A49: Инженер: | T49: Паршутин Р.Ю.
A52: Инженер: | T52: Паршутин Р.Ю.
A55: Примечание : | D55: 1. Протокол измерений касается только данных участков
D56: 2. Не разрешается перепечатка протокола без разрешения руководителя СЛ
A58: 1 | B58: При контроле недопустимых дефектов не выявлено.
A59: 2 | B59: В результате контроля выявлены дефекты:

Sheet ВИК стр. 2
A1: ='ВИК стр. 1'!A1:Y7 -> Испытательная лаборатория ООО «ГЛАВЛАБГРУПП» ИНН/КПП 7724484743/772401001, ОГРН 1197746472802 Адрес: 115304, г. Москва, ул. Каспийская, дом 22, корпус 1, стр. 5, эт. 1, пом. 1, ком 5 и 5а Аттестат аккредитации №РОСС RU.31112.И002015 Срок действия до 24 июня 2026 года.
A9: Объект контроля: | G9: Сварные соединения конструкций кровли в /о 1-2/А-Б на отм. -2,050
A10: Приложение А. Результаты визуального и измерительного контроля
A11: Таблица 1. Результаты контроля
A12: № п/п | B12: Контролируемый узел | I12: Тип шва, ГОСТ | L12: Характеристика дефектов | Q12: Соответсвие проектной документации | V12: Соответсвие НТД
A14: 1 | B14: 2 | I14: 3 | L14: 4 | Q14: 5 | V14: 6
A15: 1 | B15: Узел А. Стойка №1. Пластина 220х140х10 Закладная деталь t10 | I15: Н1 по ГОСТ 5264-80 | L15: Неравномерность сварного шва, несоответсвие катета сварного шва | Q15: Соответствует ТК-РД-КМ1 | V15: =IF(L15="Отсутствует","Соответствует СП 70.13330.2012, ГОСТ 23118-2019","Не сответствует СП 70.13330.2012, ГОСТ 23118-2019" ) -> Не сответствует СП 70.13330.2012, ГОСТ 23118-2019
A18: 2 | B18: Узел А. Стойка №2. Пластина 220х140х10 Закладная деталь t10 | I18: Н1 по ГОСТ 5264-80 | L18: Подрез более 1 мм | Q18: Соответствует ТК-РД-КМ1 | V18: =IF(L18="Отсутствует","Соответствует СП 70.13330.2012, ГОСТ 23118-2019","Не сответствует СП 70.13330.2012, ГОСТ 23118-2019" ) -> Не сответствует СП 70.13330.2012, ГОСТ 23118-2019
A21: 3 | B21: Узел А. Стойка №3. Пластина 220х140х10 Закладная деталь t10 | I21: Н1 по ГОСТ 5264-80 | L21: Сферические дефекты на глубина более 3 мм | Q21: Соответствует ТК-РД-КМ1 | V21: =IF(L21="Отсутствует","Соответствует СП 70.13330.2012, ГОСТ 23118-2019","Не сответствует СП 70.13330.2012, ГОСТ 23118-2019" ) -> Не сответствует СП 70.13330.2012, ГОСТ 23118-2019
A24: 4 | B24: Узел А. Стойка №4. Пластина 220х140х10 Закладная деталь t10 | I24: Н1 по ГОСТ 5264-80 | L24: Наплывы | Q24: Соответствует ТК-РД-КМ1 | V24: =IF(L24="Отсутствует","Соответствует СП 70.13330.2012, ГОСТ 23118-2019","Не сответствует СП 70.13330.2012, ГОСТ 23118-2019" ) -> Не сответствует СП 70.13330.2012, ГОСТ 23118-2019
A27: 5 | B27: Узел А. Стойка №5. Пластина 220х140х10 Закладная деталь t10 | I27: Н1 по ГОСТ 5264-80 | L27: Прожоги | Q27: Соответствует ТК-РД-КМ1 | V27: =IF(L27="Отсутствует","Соответствует СП 70.13330.2012, ГОСТ 23118-2019","Не сответствует СП 70.13330.2012, ГОСТ 23118-2019" ) -> Не сответствует СП 70.13330.2012, ГОСТ 23118-2019
A30: 5 | B30: Узел А. Стойка №6. Пластина 220х140х10 Закладная деталь t10 | I30: Н1 по ГОСТ 5264-80 | L30: Сужение шва | Q30: Соответствует ТК-РД-КМ1 | V30: =IF(L30="Отсутствует","Соответствует СП 70.13330.2012, ГОСТ 23118-2019","Не сответствует СП 70.13330.2012, ГОСТ 23118-2019" ) -> Не сответствует СП 70.13330.2012, ГОСТ 23118-2019
A33: 6 | B33: Узел А. Стойка №7. Пластина 220х140х10 Закладная деталь t10 | I33: Н1 по ГОСТ 5264-80 | L33: Наплывы | Q33: Соответствует ТК-РД-КМ1 | V33: =IF(L33="Отсутствует","Соответствует СП 70.13330.2012, ГОСТ 23118-2019","Не сответствует СП 70.13330.2012, ГОСТ 23118-2019" ) -> Не сответствует СП 70.13330.2012, ГОСТ 23118-2019
A34: 6.047619
A35: 6.3333333
A36: 7 | B36: Узел А. Стойка №8. Пластина 220х140х10 Закладная деталь t10 | I36: Н1 по ГОСТ 5264-80 | L36: Сферические дефекты на глубине более 3 мм | Q36: Соответствует ТК-РД-КМ1 | V36: =IF(L36="Отсутствует","Соответствует СП 70.13330.2012, ГОСТ 23118-2019","Не сответствует СП 70.13330.2012, ГОСТ 23118-2019" ) -> Не сответствует СП 70.13330.2012, ГОСТ 23118-2019
A37: 6.9047619
A38: 7.1904762
A39: 8 | B39: Узел А. Стойка №9. Пластина 220х140х10 Закладная деталь t10 | I39: Н1 по ГОСТ 5264-80 | L39: Сферические дефекты на глубине более 3 мм | Q39: Соответствует ТК-РД-КМ1 | V39: =IF(L39="Отсутствует","Соответствует СП 70.13330.2012, ГОСТ 23118-2019","Не сответствует СП 70.13330.2012, ГОСТ 23118-2019" ) -> Не сответствует СП 70.13330.2012, ГОСТ 23118-2019
A40: 7.7619048
A41: 8.047619
A42: 9 | B42: Узел А. Стойка №10. Пластина 220х140х10 Закладная деталь t10 | I42: Н1 по ГОСТ 5264-80 | L42: Сферические дефекты на глубине более 3 мм | Q42: Соответствует ТК-РД-КМ1 | V42: =IF(L42="Отсутствует","Соответствует СП 70.13330.2012, ГОСТ 23118-2019","Не сответствует СП 70.13330.2012, ГОСТ 23118-2019" ) -> Не сответствует СП 70.13330.2012, ГОСТ 23118-2019
A43: 7.7619048
A44: 8.047619
A45: 10 | B45: Узел А. Стойка №11. Пластина 220х140х10 Закладная деталь t10 | I45: Н1 по ГОСТ 5264-80 | L45: Сужение шва | Q45: Соответствует ТК-РД-КМ1 | V45: =IF(L45="Отсутствует","Соответствует СП 70.13330.2012, ГОСТ 23118-2019","Не сответствует СП 70.13330.2012, ГОСТ 23118-2019" ) -> Не сответствует СП 70.13330.2012, ГОСТ 23118-2019
A46: 7.7619048
A47: 8.047619
A48: 11 | B48: Узел А. Стойка №12. Пластина 220х140х10 Закладная деталь t10 | I48: Н1 по ГОСТ 5264-80 | L48: Сужение шва | Q48: Соответствует ТК-РД-КМ1 | V48: =IF(L48="Отсутствует","Соответствует СП 70.13330.2012, ГОСТ 23118-2019","Не сответствует СП 70.13330.2012, ГОСТ 23118-2019" ) -> Не сответствует СП 70.13330.2012, ГОСТ 23118-2019
A49: 7.7619048
A50: 8.047619
A51: 12 | B51: Узел А. Стойка №13. Пластина 220х140х10 Закладная деталь t10 | I51: Н1 по ГОСТ 5264-80 | L51: Сужение шва | Q51: Соответствует ТК-РД-КМ1 | V51: =IF(L51="Отсутствует","Соответствует СП 70.13330.2012, ГОСТ 23118-2019","Не сответствует СП 70.13330.2012, ГОСТ 23118-2019" ) -> Не сответствует СП 70.13330.2012, ГОСТ 23118-2019
A52: 7.7619048
A53: 8.047619
A54: 13 | B54: Узел А. Стойка №14. Пластина 220х140х10 Закладная деталь t10 | I54: Н1 по ГОСТ 5264-80 | L54: Сужение шва | Q54: Соответствует ТК-РД-КМ1 | V54: =IF(L54="Отсутствует","Соответствует СП 70.13330.2012, ГОСТ 23118-2019","Не сответствует СП 70.13330.2012, ГОСТ 23118-2019" ) -> Не сответствует СП 70.13330.2012, ГОСТ 23118-2019
A55: 7.7619048
A56: 8.047619
A57: 14 | B57: Узел А. Стойка №15. Пластина 220х140х10 Закладная деталь t10 | I57: Н1 по ГОСТ 5264-80 | L57: Сужение шва | Q57: Соответствует ТК-РД-КМ1 | V57: =IF(L57="Отсутствует","Соответствует СП 70.13330.2012, ГОСТ 23118-2019","Не сответствует СП 70.13330.2012, ГОСТ 23118-2019" ) -> Не сответствует СП 70.13330.2012, ГОСТ 23118-2019
A58: 7.7619048
A59: 8.047619
A60: 15 | B60: Узел А. Стойка №16. Пластина 220х140х10 Закладная деталь t10 | I60: Н1 по ГОСТ 5264-80 | L60: Сужение шва | Q60: Соответствует ТК-РД-КМ1 | V60: =IF(L60="Отсутствует","Соответствует СП 70.13330.2012, ГОСТ 23118-2019","Не сответствует СП 70.13330.2012, ГОСТ 23118-2019" ) -> Не сответствует СП 70.13330.2012, ГОСТ 23118-2019
...

Sheet ВИК стр. 3
A1: Испытательная лаборатория ООО «ГЛАВЛАБГРУПП» ИНН/КПП 7724484743/772401001, ОГРН 1197746472802 Адрес: 115304, г. Москва, ул. Каспийская, дом 22, корпус 1, стр. 5, эт. 1, пом. 1, ком 5 и 5а Аттестат аккредитации №РОСС RU.31112.И002015 Срок действия до 24 июня 2026 года.
A9: Приложение Б. Фотофиксация дефектов
A20: Фото 1. Неравномерная чешуйчатость шва | F20: Фото 2. Недостаточная величина катета шва | K20: Фото 3. Механические повреждения шва | P20: Фото 4. Утоньшение основого металла | U20: Фото 5. Несплавление по контуру шва
A32: Фото 1. Неравномерная чешуйчатость шва | F32: Фото 2. Недостаточная величина катета шва | K32: Фото 1. Механические повреждения шва | P32: Фото 1. Утоньшение основого металла | U32: Фото 1. Несплавление по контуру шва
A44: Фото 1. Неравномерная чешуйчатость шва | F44: Фото 2. Недостаточная величина катета шва | K44: Фото 1. Механические повреждения шва | P44: Фото 1. Утоньшение основого металла | U44: Фото 1. Несплавление по контуру шва
A56: Фото 1. Неравномерная чешуйчатость шва | F56: Фото 2. Недостаточная величина катета шва | K56: Фото 1. Механические повреждения шва | P56: Фото 1. Утоньшение основого металла | U56: Фото 1. Несплавление по контуру шва
V84: Симоров А.Ю.
A85: Ответственные исполнители:
A87: Инженер:
V88: Паршутин Р.Ю.
A89: Инженер:
V90: Паршутин Р.Ю.
A93: Испытательная лаборатория ООО «ГЛАВЛАБГРУПП» ИНН/КПП 7724484743/772401001, ОГРН 1197746472802 Адрес: 115304, г. Москва, ул. Каспийская, дом 22, корпус 1, стр. 5, эт. 1, пом. 1, ком 5 и 5а Аттестат аккредитации №РОСС RU.31112.И002015 Срок действия до 24 июня 2026 года.
A101: Объект контроля: | G101: Сварные соединения распорной системы в/о 1-10-А-Д с отм. -5,650 до отм. +2,360
A102: Тип сварных соединений: | G102: С17 по ГОСТ 5264-80* или У4 по ГОСТ 14771-76 или другое
A104: Таблица 1. Параметры геометрии шва:
A105: № п/п | C105: Контролируемый параметр | J105: Обозначение | M105: Требования НД | Q105: Результаты измерений, мм | V105: Соответствует / не соответствует
C107: 2 | J107: 3 | M107: 4 | Q107: 5 | V107: 6
A108: 1 | C108: Ширина шва | J108: e | M108: ="+20(-2;+1)" -> +20(-2;+1) | Q108: 20-25 | V108: Соответствует
A109: 2 | C109: Высота усиления (выпуклость) | J109: g | M109: ="+10(-2;+1)" -> +10(-2;+1) | Q109: 20-25 | V109: Соответствует
A110: 3 | C110: Катет | J110: h | M110: Не более 0,5 мм | Q110: 20-25 | V110: Соответствует
A112: Таблица 2. Результаты измерительного контроля дефектов
A113: № п/п | C113: Наименование дефекта | J113: Размер (длина/диаметр/глубина, мм) | Q113: Допустимый размер (по НД) | V113: Соответствует / не соответствует
A115: 1 | C115: 2 | J115: 3 | Q115: 4 | V115: 5
A116: 1 | C116: Пора одиночная | J116: ="+20(-2;+1)" -> +20(-2;+1) | Q116: 20-25 | V116: Соответствует
A117: 2 | C117: Подрез | J117: ="+10(-2;+1)" -> +10(-2;+1) | Q117: не более 1 мм | V117: Соответствует
A118: 3 | J118: Не более 0,5 мм | Q118: не более 1 мм | V118: Соответствует
A119: 4 | C119: Трещина | J119: - | Q119: Не допускается | V119: Соответствует
A120: 5 | C120: другие дефекты см. гост 5817-2025 | J120: - | V120: Да
A122: Заключение:
A123: ="При контроле недопустимых дефектов не выявлено. "&G101&", общей длиной 0,0 м.п. соответствуют требованиям ГОСТ 14098-2014, СП 70.13330.2012." -> При контроле недопустимых дефектов не выявлено. Сварные соединения распорной системы в/о 1-10-А-Д с отм. -5,650 до отм. +2,360, общей длиной 0,0 м.п. соответствуют требованиям ГОСТ 14098-2014, СП 70.13330.2012.
A125: Заведующий строительной лабораторией:
T126: Симоров А.Ю.
A127: Ответственные исполнители:
A129: Инженер:
T130: Паршутин Р.Ю.
A131: Инженер:
T132: Паршутин Р.Ю.
A133: Примечание :
A135: Испытательная лаборатория ООО «ГЛАВЛАБГРУПП» ИНН/КПП 7724484743/772401001, ОГРН 1197746472802 Адрес: 115304, г. Москва, ул. Каспийская, дом 22, корпус 1, стр. 5, эт. 1, пом. 1, ком 5 и 5а Аттестат аккредитации №РОСС RU.31112.И002015 Срок действия до 24 июня 2026 года.
...

Sheet УЗК стр. 1
A1: Испытательная лаборатория ООО «ГЛАВЛАБГРУПП» ИНН/КПП 7724484743/772401001, ОГРН 1197746472802 Адрес: 115304, г. Москва, ул. Каспийская, дом 22, корпус 1, стр. 5, эт. 1, пом. 1, ком 5 и 5а Аттестат аккредитации №РОСС RU.31112.И002015 Срок действия до 24 июня 2026 года. | Z1: Офис | AA1: Дефектоскоп ультразвуковой А1212 MASTER, зав. № 4142768, свидетельство о поверке № С-АКЗ/17-09-2025/466478509, действительно до 16.09.2026; Преобразователь S5182 2,5-65, частота 2,5 МГц, угол ввода 65 град.; Набор образцов шероховатости поверхности ОШС-ШП, зав. № 1693-1690, сертификат о калибровке № К0015-0111/25, действителен до 31.10.2026
Z2: Влад | AA2: Дефектоскоп ультразвуковой А1211 Mini, зав № 3161189, свидетельство о поверке № С-АКЗ/15-07-2025/447786693, действительно до 14.07.2026; Преобразователь S5182, частота 2,5 МГц, угол ввода 65 град.; Набор образцов шероховатости поверхности ОШС-ШП, зав. № 1693-1690, сертификат о калибровке № К0015-0111/25, действителен до 31.10.2026
Z3: Рус | AA3: Ультразвуковой дефектоскоп УСД-50, зав № 243092, свидетельство о поверке № С-АКЗ/03-07-2025/444975552, действительно до 02.07.2026; Преобразователь AN5065, частота 5,0 МГц, угол ввода 65 град.; Набор образцов шероховатости поверхности ОШС-ШП, зав. № 1693-1690, сертификат о калибровке № К0015-0111/25, действителен до 31.10.2026
Z4: Арм | AA4: Дефектоскоп ультразвуковой АРМС-МГ4, зав. №116, сертификат о калибровке № С-ГА/17-03-2026/513280521 действительно до 16.03.2027; Набор образцов шероховатости поверхности ОШС-ШП, зав. № 1693-1690, сертификат о калибровке № К0015-0111/25, действителен до 31.10.2026
R9: УТВЕРЖДАЮ:
R10: Заведующий строительной лабораторией:
W11: Симоров А.Ю.
R12: (подпись)
R13: =TEXT($G$25,"[$-FC19]«ДД» ММММ ГГГГ \г.") -> «05» февраля 2026 г.
A15: ="Протокол №"&MID(CELL("filename",A1),SEARCH("]",CELL("filename"))+1,255)&".УДС от "&TEXT($G$25,"ДД.ММ.ГГГГ")&"" -> Протокол №УЗК стр. 1.УДС от 05.02.2026
A16: Ультразвукового контроля по ГОСТ 55724-2013
A18: Заказчик : | G18: ООО «АТЛАНТ»
A19: Исполнитель: | G19: ООО «ГЛАВЛАБГРУПП»
A20: Наименование объекта: | G20: Квартал Издание. «Комплекс жилых домов переменной этажности со встроенно-пристроенными помещениями общественного назначения и подземной автостоянкой»
A22: Адрес объекта: | G22: г. Москва, внутригородское образование Нижегородское, шоссе Перовское, земельный участок с кадастровым номером 77:04:0002001:8601
A24: Вид контроля: | G24: Ультразвуковой контроль сварных соединений
A25: Дата проведения испытаний: | G25: 46058
A26: Методика испытаний: | G26: ГОСТ Р 55724-2013 Контроль неразрушающий. Соединения сварные. Методы ультразвуковые.
A27: Оценка качества: | G27: ='ВИК стр. 1'!G28 -> ГОСТ 23118-2019 «Конструкции строительные, стальные. Общие технические условия», СП 70.13330.2012 «Несущие и ограждающие конструкции».
A29: Способ сварки: | G29: ='ВИК стр. 1'!G30 -> ГОСТ 5264-80 «Ручная дуговая сварка. Соединения сварные. Основные типы, конструктивные элементы и размеры».
A31: Используемое оборудование: | G31: Дефектоскоп ультразвуковой А1212 MASTER, зав. № 4142768, свидетельство о поверке № С-АКЗ/17-09-2025/466478509, действительно до 16.09.2026; Преобразователь S5182 2,5-65, частота 2,5 МГц, угол ввода 65 град.; Набор образцов шероховатости поверхности ОШС-ШП, зав. № 1693-1690, сертификат о калибровке № К0015-0111/25, действителен до 31.10.2026
A36: Исполнитель: | D36: ='ВИК стр. 1'!D38 -> контроль выполнил дефектоскопист II уровня____________________Паршутин Р.Ю. (удостоверение №0071-0278 (действительно до 09.2026)
A38: Заключение: | Z38: Сварные соединения распорной системы в/о 19с-22с/Ас-Дс с отм. -5,650 до отм. +2,360, общей длиной 10,5 м.п. соответствуют требованиям
A39: ="При контроле недопустимых дефектов не выявлено. Тип шва Т1, С8, Н1 по "&G29&"" -> При контроле недопустимых дефектов не выявлено. Тип шва Т1, С8, Н1 по ГОСТ 5264-80 «Ручная дуговая сварка. Соединения сварные. Основные типы, конструктивные элементы и размеры».
A41: =_xlfn.CONCAT(Z38,G27) -> Сварные соединения распорной системы в/о 19с-22с/Ас-Дс с отм. -5,650 до отм. +2,360, общей длиной 10,5 м.п. соответствуют требованиям ГОСТ 23118-2019 «Конструкции строительные, стальные. Общие технические условия», СП 70.13330.2012 «Несущие и ограждающие конструкции».
A44: Результаты ультразвукового контроля представлены в приложении А.
A46: Ответственные исполнители:
A48: Инженер: | T48: Паршутин Р.Ю.
A51: Инженер: | T51: Паршутин Р.Ю.
A54: Примечание : | D54: 1. Протокол измерений касается только данных участков
D55: 2. Не разрешается перепечатка протокола без разрешения руководителя СЛ
A56: 1 | B56: При контроле недопустимых дефектов не выявлено.
A57: 2 | B57: В результате контроля выявлены дефекты.

Sheet УЗК стр. 2
A1: Испытательная лаборатория ООО «ГЛАВЛАБГРУПП» ИНН/КПП 7724484743/772401001, ОГРН 1197746472802 Адрес: 115304, г. Москва, ул. Каспийская, дом 22, корпус 1, стр. 5, эт. 1, пом. 1, ком 5 и 5а Аттестат аккредитации №РОСС RU.31112.И002015 Срок действия до 24 июня 2026 года.
A8: Приложение А. Результаты ультразвукового контроля
A9: Объект контроля: | G9: Сварные соединения распорной системы в/о 1-10-А-Д с отм. -5,650 до отм. +2,360
A10: Эскиз объекта контроля с указанием точки отсчета и направления координат:
A30: Таблица 1. Результаты измерительного контроля дефектов
A31: позиция сканир-я | C31: А, дБ | E31: У, мм | G31: X, мм | I31: Xc, мм | K31: l1, мм | M31: l2, мм | O31: l2-l1, мм | Q31: Схема расположения индикаций | W31: Соответствует / не соответствует
A33: 1 | W33: соответствует
A34: 2 | W34: соответствует
A35: 1 | W35: соответствует
A36: 2 | W36: соответствует
A37: 1 | W37: соответствует
A38: 2 | W38: соответствует
A39: 1 | W39: соответствует
A40: 2 | W40: соответствует
A42: Заключение:
A43: =""&G9&", общей длиной 10,5 м.п. соответствуют требованиям "&'ВИК стр. 1'!G30&"" -> Сварные соединения распорной системы в/о 1-10-А-Д с отм. -5,650 до отм. +2,360, общей длиной 10,5 м.п. соответствуют требованиям ГОСТ 5264-80 «Ручная дуговая сварка. Соединения сварные. Основные типы, конструктивные элементы и размеры».
A46: Заведующий строительной лабораторией:
T47: Симоров А.Ю.
A48: Ответственные исполнители:
A50: Инженер:
T51: Паршутин Р.Ю.
A52: Инженер:
T53: Паршутин Р.Ю.
A54: Примечание :
A56: Испытательная лаборатория ООО «ГЛАВЛАБГРУПП» ИНН/КПП 7724484743/772401001, ОГРН 1197746472802 Адрес: 115304, г. Москва, ул. Каспийская, дом 22, корпус 1, стр. 5, эт. 1, пом. 1, ком 5 и 5а Аттестат аккредитации №РОСС RU.31112.И002015 Срок действия до 24 июня 2026 года.
A64: Объект контроля: | G64: Сварные соединения распорной системы в/о 1-10-А-Д с отм. -5,650 до отм. +2,360
A65: Тип сварных соединений: | G65: С17 по ГОСТ 5264-80* или У4 по ГОСТ 14771-76 или другое
A67: Таблица 1. Параметры геометрии шва:
A68: № п/п | C68: Контролируемый параметр | J68: Обозначение | M68: Требования НД | Q68: Результаты измерений, мм | V68: Соответствует / не соответствует
C70: 2 | J70: 3 | M70: 4 | Q70: 5 | V70: 6
A71: 1 | C71: Ширина шва | J71: e | M71: ="+20(-2;+1)" -> +20(-2;+1) | Q71: 20-25 | V71: Соответствует
A72: 2 | C72: Высота усиления (выпуклость) | J72: g | M72: ="+10(-2;+1)" -> +10(-2;+1) | Q72: 20-25 | V72: Соответствует
A73: 3 | C73: Катет | J73: h | M73: Не более 0,5 мм | Q73: 20-25 | V73: Соответствует
A75: Таблица 2. Результаты измерительного контроля дефектов
A76: № п/п | C76: Наименование дефекта | J76: Размер (длина/диаметр/глубина, мм) | Q76: Допустимый размер (по НД) | V76: Соответствует / не соответствует
A78: 1 | C78: 2 | J78: 3 | Q78: 4 | V78: 5
A79: 1 | C79: Пора одиночная | J79: ="+20(-2;+1)" -> +20(-2;+1) | Q79: 20-25 | V79: Соответствует
A80: 2 | C80: Подрез | J80: ="+10(-2;+1)" -> +10(-2;+1) | Q80: не более 1 мм | V80: Соответствует
A81: 3 | J81: Не более 0,5 мм | Q81: не более 1 мм | V81: Соответствует
A82: 4 | C82: Трещина | J82: - | Q82: Не допускается | V82: Соответствует
...
