Workbook

Sheet Рассчеты (3)
A10: Протокол об испытаниях №0000.ВС/04.24 от 01.04.2024
A11: Анкеры механические для крепления в бетоне по ГОСТ 56731-2023
A13: Основание для проведения работ: | D13: СЧЕТ № 23305/14-11-25/2 от 14 ноября 2025 года
A14: Заказчик :
A15: Наименование объекта:
A16: Адрес объекта:
A17: Дата испытаний
A18: Вид испытаний: | D18: Испытание на вырыв
A19: Методика проведения испытаний: | D19: ГОСТ 56731-2023 Анкера механические для крепления в бетоне. Методы испытаний
A20: СТО-44416204-010-2010 «Крепления анкерные. Метод определения несущей способности по результатам натурных испытаний»
A21: Оборудование, инструменты: | D21: Измеритель адгезии ПСО-100МГ4АД зав. 2573, свидетельство о поверке «ВИК-НДТ», зав. №3581, свидетельство о калибровке № К0034-1001/24 действительно до 09.01.2025;
A22: № С-ГА/24-06-2025/444021486 действительно до 23.06.2027; Измеритель параметров микроклимата; Метеоскоп-М; "МЕТЕОСКОП-М"; Рег. № 32014-11 зав. № 615022, свидетельство о поверке №С-ДЮП/05-07-2024/353605602 действительно до 04.07.2026. Перфоратор DeWALT, рулетка, молоток.
A25: Описание и тип анкера, наименование изготовителя: | D25: Дюбель для теплоизоляции 10х180мм ИЗТ, с металлическим стержнем и термоголовкой - ООО "HILTI"
A26: Таблица 1
A27: Дата изготовления | B27: Место проведения | D27: Материал | E27: Метод сверления | F27: t, ℃ | G27: Глубина заделки, мм | H27: Расстояние между анкерами, мм | I27: Описание и тип анкера, наименование изготовителя: | N27: Случмежду
A28: 46059 | B28: Стена в/о 1-2/А-Б на отм. +1,050 | D28: Тяжелый бетон В25 | E28: Бурение | F28: 15 | G28: 36 | H28: 300 | I28: Анкер-Ш 10х180мм ИЗТ, с металлическим стержнем и термоголовкой - ООО "HILTI" | N28: =RANDBETWEEN(450,500)/10 -> 47.8
B30: № образца в серии
A31: № испытания | B31: Анкер-Ш 10х180мм | C31: Анкер-Ш 12х180мм
A32: 1 | B32: =RANDBETWEEN(450,500)/10 -> 48.5 | L32: 1 | M32: нарушение контакта анкера с бетоном | T32: Нагрузка
A33: 2 | B33: =RANDBETWEEN(450,500)/10 -> 49.9 | L33: 2 | M33: выкалывание бетона основания | T33: 1
A34: 3 | B34: =RANDBETWEEN(450,500)/10 -> 49.1 | L34: 3 | M34: разрушение анкера по стали | T34: 2
A35: 4 | B35: =RANDBETWEEN(450,500)/10 -> 45.8 | T35: 3
A36: 5 | B36: =RANDBETWEEN(450,500)/10 -> 45.8 | T36: 4
A37: 6 | B37: =RANDBETWEEN(450,500)/10 -> 48.1 | L37: 1 | M37: нарушение контакта анкера с бетоном | T37: 5
A38: 7 | B38: =RANDBETWEEN(450,500)/10 -> 49.2 | L38: 2 | M38: выкалывание бетона основания | T38: 6
A39: 8 | B39: =RANDBETWEEN(450,500)/10 -> 45.8 | L39: 3 | M39: разрушение анкера по стали | T39: 7
A40: 9 | B40: =RANDBETWEEN(450,500)/10 -> 47.6 | T40: 8
A41: 10 | B41: =RANDBETWEEN(450,500)/10 -> 47.5 | T41: 9
L42: 1 | M42: нарушение контакта анкера с бетоном | T42: 10
A43: Таблица 3 | T43: 15
A44: Среднее значение нагрузки N, кН: | C44: Среднеквадратическое отклонение S, кН: | E44: Коэф. вариации v, %: | F44: Коэф., К: | G44: Коэф. надёжности, m: | H44: Коэф. условий работы: | I44: Расч сопротивление | J44: Расчётное сопротивление с учетом коэффициента условий работы:
A45: 1 | C45: 2 | E45: 3 | F45: 4 | G45: 5 | H45: 6 | I45: 7
A46: =AVERAGE(B32:B41) -> 47.73 | C46: =1/A46*SQRT((B32-A46)^2/MAX(A32:A41)-1) -> #NUM!
A49: Коэффициент надёжности по материалу, m:
A50: Коэффициент условий работы:
A51: Расчётное сопротивление анкерного крепления:
A52: Расчётное сопротивление анкерного крепления с учетом коэффициента условий работы:
A53: Заведующий строительной лабораторией: | G53: _________________/Симоров А.Ю./
A55: Ответственные исполнители:
A57: Инженер: | G57: _________________/Симоров А.Ю./
...

Sheet Рассчет
C2: Показания прибора | S2: Шаг | U2: Степ. коэф
R3: Макс
C4: Образец №1 | G4: F, кН | I4: 0 | J4: =J5^LOG(J5,$U4) -> 1.0314166 | K4: =K5^LOG(K5,$U4) -> 1.4429903 | L4: =L5^LOG(L5,$U4) -> 3.09353 | M4: =M5^LOG(M5,$U4) -> 6.8471437 | N4: =N5^LOG(N5,$U4) -> 14.658031 | O4: =O5^LOG(O5,$U4) -> 29.989847 | P4: =P5^LOG(P5,$U4) -> 58.676732 | Q4: =Q5^LOG(Q5,$U4) -> 110.19761 | R4: 88.51 | S4: =R5/9 -> 0.85555556 | U4: =LN(R4)/LN(R5) -> 2.1962918
G5: D, мм | I5: 0 | J5: =K5-$S4 -> 0.85555556 | K5: =L5-$S4 -> 1.7111111 | L5: =M5-$S4 -> 2.5666667 | M5: =N5-$S4 -> 3.4222222 | N5: =O5-$S4 -> 4.2777778 | O5: =P5-$S4 -> 5.1333333 | P5: =Q5-$S4 -> 5.9888889 | Q5: =R5-$S4 -> 6.8444444 | R5: 7.7
C6: Образец №2 | G6: F, кН | I6: 0 | J6: =J7^$U6 -> 0.16049844 | K6: =K7^$U6 -> 1.1302689 | L6: =L7^$U6 -> 3.54047 | M6: =M7^$U6 -> 7.9596279 | N6: =N7^$U6 -> 14.920891 | O6: =O7^$U6 -> 24.932849 | P6: =P7^$U6 -> 38.485435 | Q6: =Q7^$U6 -> 56.05363 | R6: 78.1 | S6: =R7/9 -> 0.52222222 | U6: =LN(R6)/LN(R7) -> 2.8160349
G7: D, мм | I7: 0 | J7: =K7-$S6 -> 0.52222222 | K7: =L7-$S6 -> 1.0444444 | L7: =M7-$S6 -> 1.5666667 | M7: =N7-$S6 -> 2.0888889 | N7: =O7-$S6 -> 2.6111111 | O7: =P7-$S6 -> 3.1333333 | P7: =Q7-$S6 -> 3.6555556 | Q7: =R7-$S6 -> 4.1777778 | R7: 4.7
C8: Образец №3 | G8: F, кН | I8: 0 | J8: =J9^$U8 -> 0.015723279 | K8: =K9^$U8 -> 0.25433926 | L8: =L9^$U8 -> 1.2958573 | M8: =M9^$U8 -> 4.1141838 | N8: =N9^$U8 -> 10.079825 | O8: =O9^$U8 -> 20.961747 | P8: =P9^$U8 -> 38.928804 | Q8: =Q9^$U8 -> 66.550905 | R8: 106.8 | S8: =R9/9 -> 0.35555556 | U8: =LN(R8)/LN(R9) -> 4.0157801
G9: D, мм | I9: 0 | J9: =K9-$S8 -> 0.35555556 | K9: =L9-$S8 -> 0.71111111 | L9: =M9-$S8 -> 1.0666667 | M9: =N9-$S8 -> 1.4222222 | N9: =O9-$S8 -> 1.7777778 | O9: =P9-$S8 -> 2.1333333 | P9: =Q9-$S8 -> 2.4888889 | Q9: =R9-$S8 -> 2.8444444 | R9: 3.2
C10: Образец №4 | G10: F, кН | I10: 0 | J10: =J11^$U10 -> 0.066726466 | K10: =K11^$U10 -> 0.67489458 | L10: =L11^$U10 -> 2.612684 | M10: =M11^$U10 -> 6.8261175 | N10: =N11^$U10 -> 14.377768 | O10: =O11^$U10 -> 26.42559 | P10: =P11^$U10 -> 44.209464 | Q10: =Q11^$U10 -> 69.041715 | R10: 102.3 | S10: =R11/9 -> 0.44444444 | U10: =LN(R10)/LN(R11) -> 3.3383312
G11: D, мм | I11: 0 | J11: =K11-$S10 -> 0.44444444 | K11: =L11-$S10 -> 0.88888889 | L11: =M11-$S10 -> 1.3333333 | M11: =N11-$S10 -> 1.7777778 | N11: =O11-$S10 -> 2.2222222 | O11: =P11-$S10 -> 2.6666667 | P11: =Q11-$S10 -> 3.1111111 | Q11: =R11-$S10 -> 3.5555556 | R11: 4
C12: Образец №5 | G12: F, кН | I12: 0 | J12: =J13^$U12 -> 0.037473091 | K12: =K13^$U12 -> 0.44942689 | L12: =L13^$U12 -> 1.9221984 | M12: =M13^$U12 -> 5.3901218 | N12: =N13^$U12 -> 11.993323 | O12: =O13^$U12 -> 23.053547 | P12: =P13^$U12 -> 40.057674 | Q12: =Q13^$U12 -> 64.645472 | R12: 98.6 | S12: =R13/9 -> 0.4 | U12: =LN(R12)/LN(R13) -> 3.5841595
G13: D, мм | I13: 0 | J13: =K13-$S12 -> 0.4 | K13: =L13-$S12 -> 0.8 | L13: =M13-$S12 -> 1.2 | M13: =N13-$S12 -> 1.6 | N13: =O13-$S12 -> 2 | O13: =P13-$S12 -> 2.4 | P13: =Q13-$S12 -> 2.8 | Q13: =R13-$S12 -> 3.2 | R13: 3.6
A15: Вставлять от руки
A16: Коэф К | G16: 3.4
A17: Бетон R25-60 | G17: В | H17: 25 | J17: (если это бетон)
A19: n | C19: Max | J19: ^2 | N19: Сумма ^2 | P19: Корень | X19: Rан
X20: Мех. | AA20: Тарельч.
A21: 1 | C21: 30.33 | G21: =C21-$L$21 -> -0.038 | J21: =G21^2 -> 0.001444 | L21: =AVERAGE(C21:F30) -> 30.368 | N21: =SUM(J21:K30) -> 1.51216 | P21: =SQRT((N21/(C31-1))) -> 0.40989972 | R21: =P21/L21 -> 0.013497751 | U21: =L21*(1-G16*R21) -> 28.974341 | X21: =U21/3 -> 9.6581137 | AA21: =U21/5 -> 5.7948682
A22: 2 | C22: 30.38 | G22: =C22-$L$21 -> 0.012 | J22: =G22^2 -> 0.000144
A23: 3 | C23: 30.53 | G23: =C23-$L$21 -> 0.162 | J23: =G23^2 -> 0.026244
A24: 4 | C24: 30.82 | G24: =C24-$L$21 -> 0.452 | J24: =G24^2 -> 0.204304
A25: 5 | C25: 30.56 | G25: =C25-$L$21 -> 0.192 | J25: =G25^2 -> 0.036864
A26: 6 | C26: 30.26 | G26: =C26-$L$21 -> -0.108 | J26: =G26^2 -> 0.011664
A27: 7 | C27: 30.8 | G27: =C27-$L$21 -> 0.432 | J27: =G27^2 -> 0.186624
A28: 8 | C28: 30.21 | G28: =C28-$L$21 -> -0.158 | J28: =G28^2 -> 0.024964
A29: 9 | C29: 29.36 | G29: =C29-$L$21 -> -1.008 | J29: =G29^2 -> 1.016064
A30: 10 | C30: 30.43 | G30: =C30-$L$21 -> 0.062 | J30: =G30^2 -> 0.003844
A31: N | C31: =MAX(A19:B52) -> 10
A33: Приложение А
A35: Бетон | F35: Ячеистый бетон | K35: Кирпич

Sheet старый по СТО 2010 года
B1: 1. Выбери тип анкера
B2: Стальные механические (все типы) и клеевые (химические) | G2: =IF(B2=E24,J24,J25) -> 3
B3: 2. Введи значения с прибора в зеленое поле
C4: Значение | D4: Ni-Nm | E4: (Ni-Nm)^2 | F4: 3 | G4: Sср. Откл | H4: 1/Nm | I4: v | J4: Nn | K4: k | L4: Ran
B5: 1 | C5: 30.33 | D5: =C5-$C$15 -> -0.038 | E5: =D5^2 -> 0.001444 | F5: =E15/(MAX(B5:B14)-1) -> 0.16801778 | G5: =SQRT(F5) -> 0.40989972 | H5: =1/C15 -> 0.032929399 | I5: =G5/C15 -> 0.013497751 | J5: =C15*(1-(I5/100)*LOOKUP(MAX(B5:B14),B25:B32,C25:C32)) -> 30.357474 | K5: =LOOKUP(MAX(B5:B14),B25:B32,C25:C32) -> 2.568 | L5: =(C15*(1-LOOKUP(MAX(B5:B14),B25:B32,C25:C32)*I5))/G2 -> 9.7717925
B6: 2 | C6: 30.38 | D6: =C6-$C$15 -> 0.012 | E6: =D6^2 -> 0.000144
B7: 3 | C7: 30.53 | D7: =C7-$C$15 -> 0.162 | E7: =D7^2 -> 0.026244
B8: 4 | C8: 30.82 | D8: =C8-$C$15 -> 0.452 | E8: =D8^2 -> 0.204304
B9: 5 | C9: 30.56 | D9: =C9-$C$15 -> 0.192 | E9: =D9^2 -> 0.036864
B10: 6 | C10: 30.26 | D10: =C10-$C$15 -> -0.108 | E10: =D10^2 -> 0.011664
B11: 7 | C11: 30.8 | D11: =C11-$C$15 -> 0.432 | E11: =D11^2 -> 0.186624
B12: 8 | C12: 30.21 | D12: =C12-$C$15 -> -0.158 | E12: =D12^2 -> 0.024964
B13: 9 | C13: 29.36 | D13: =C13-$C$15 -> -1.008 | E13: =D13^2 -> 1.016064
B14: 10 | C14: 30.43 | D14: =C14-$C$15 -> 0.062 | E14: =D14^2 -> 0.003844
B15: Nm | C15: =AVERAGE(C5:C14) -> 30.368 | D15: сумма | E15: =SUM(E5:E14) -> 1.51216
B23: Не трогаем | E23: Не трогаем
B24: число | C24: k | E24: Стальные механические (все типы) и клеевые (химические) | J24: 3
B25: 3 | C25: 5.31 | E25: Пластиковые и тарельчатые анкеры (все типы) | J25: 5
B26: 4 | C26: 3.957
B27: 5 | C27: 3.4
B28: 6 | C28: 3.091
B29: 7 | C29: 2.894
B30: 8 | C30: 2.755
B31: 9 | C31: 2.649
B32: 10 | C32: 2.568

Sheet рассчет 2.0
B1: 1. Выбери тип анкера
B2: Пластиковые и тарельчатые анкеры (все типы) | G2: =IF(B2=E19,J19,J20) -> 5
B3: 2. Введи значения с прибора в зеленое поле
B4: Ni | C4: Значение | D4: Ni-Nm | E4: (Ni-Nm)^2 | F4: 3 | G4: Sср. Откл | H4: 1/Nm | I4: v | J4: Nn | K4: k | L4: Ran
B5: 1 | C5: 8.77 | D5: =C5-$C$10 -> 0.92 | E5: =D5^2 -> 0.8464 | F5: =E10/(MAX(B5:B9)-1) -> 2.84865 | G5: =SQRT(F5) -> 1.6877944 | H5: =1/C10 -> 0.12738854 | I5: =H5*G5*100 -> 21.500566 | J5: =C10*(1-(I5/100)*LOOKUP(MAX(B5:B9),B20:B27,C20:C27)) -> 2.111499 | K5: =LOOKUP(MAX(B5:B9),B20:B27,C20:C27) -> 3.4 | L5: =J5/G2 -> 0.4222998 | M5: Нарушение сцепление анкера со строительным основанием, приводящее к его вытягиванию
B6: 2 | C6: 6.13 | D6: =C6-$C$10 -> -1.72 | E6: =D6^2 -> 2.9584 | M6: Нарушение сцепление анкера со строительным основанием, приводящее к его вытягиванию
B7: 3 | C7: 9.17 | D7: =C7-$C$10 -> 1.32 | E7: =D7^2 -> 1.7424 | M7: Нарушение сцепление анкера со строительным основанием, приводящее к его вытягиванию
B8: 4 | C8: 9.28 | D8: =C8-$C$10 -> 1.43 | E8: =D8^2 -> 2.0449 | M8: Нарушение сцепление анкера со строительным основанием, приводящее к его вытягиванию
B9: 5 | C9: 5.9 | D9: =C9-$C$10 -> -1.95 | E9: =D9^2 -> 3.8025 | M9: Нарушение сцепление анкера со строительным основанием, приводящее к его вытягиванию
B10: Nm | C10: =AVERAGE(C5:C9) -> 7.85 | D10: сумма | E10: =SUM(E5:E9) -> 11.3946
B18: Не трогаем | E18: Не трогаем
B19: число | C19: k | E19: Стальные механические (все типы) и клеевые (химические) | J19: 3
B20: 3 | C20: 5.31 | E20: Пластиковые и тарельчатые анкеры (все типы) | J20: 5
B21: 4 | C21: 3.957
B22: 5 | C22: 3.4
B23: 6 | C23: 3.091
B24: 7 | C24: 2.894
B25: 8 | C25: 2.755
B26: 9 | C26: 2.649
B27: 10 | C27: 2.568

Sheet 3888
A1: Испытательная лаборатория ООО «ГЛАВЛАБГРУПП» ИНН/КПП 7724484743/772401001, ОГРН 1197746472802 Адрес: 115304, г. Москва, ул. Каспийская, дом 22, корпус 1, стр. 5, эт. 1, пом. 1, ком 5 и 5а Аттестат аккредитации №РОСС RU.31112.И002015 Срок действия до 24 июня 2026 года. | Z1: Нарушение сцепление анкера со строительным основанием, приводящее к его вытягиванию
Z2: Выкалывание материала строительного основания с образованием конуса
Z3: Разрушение анкера по стали при достижении усилия разрыва
A9: ="Протокол об испытаниях №"&MID(CELL("filename",A1),SEARCH("]",CELL("filename"))+1,255)&".АК от "&TEXT($G$17,"ДД.ММ.ГГГГ")&"" -> Протокол об испытаниях №3888.АК от 25.03.2026
A10: Крепления анкерные по ГОСТ Р 71447-2024
A12: Заказчик : | G12: ООО «Альтстрой»
A13: Исполнитель: | G13: ООО «ГЛАВЛАБГРУПП»
A14: Наименование объекта: | G14: «Жилой дом с инженерными сетями и благоустройством территории»
A15: Адрес объекта: | G15: г. Зеленоград, анфиловский пр-кт, з/у 927
A16: Вид испытаний: | G16: Испытание на вырыв
A17: Дата проведения испытаний: | G17: 46106
A18: Методика испытаний: | G18: ГОСТ Р 71447-2024 Крепления анкерные. Метод натурного испытания.
A19: Используемое оборудование: | G19: Прибор типа ПСО-100МГ4АД, зав. № 2573, свидетельство о поверке № С-ГА/24-06-2025/444021486, действительно до 23.06.2027; Измеритель параметров микроклимата «Метеоскоп-М», рег. № 32014-11, зав. № 615022, свидетельство о поверке №С-ДЮП/05-07-2024/353605602, действительно до 04.07.2026; Перфоратор DeWALT; Рулетка; Молоток
A23: Сведения об установке анкера: | G23: Направление сверления параллельно оси установки анкера, очистка отвертия была произведена сжатым воздухом, при визуальном контроле строительного основания дефектов не обнаружено; Установка анкерных креплений производилась заказчиком; Использованное оборудование для установки анкера: Бур SDS plus Hilton 12, гайковёрт*
A26: Таблица 1. Сведения о материалах
A27: Место проведения испытаний* | J27: Метод сверления* | L27: t, ℃ | M27: Глубина заделки, мм* | O27: Расстояние между анкерами и краем, мм | R27: Описание и тип анкера, наименование изготовителя*
A30: Стена в/о 1-2/А-Б на отм. +1,050 | J30: Бурение | L30: +15 | M30: 36 | O30: 300/300 | R30: Анкер-Ш 10х180мм ИЗТ, с металлическим стержнем и термоголовкой - ООО "HILTI"
A32: Таблица 2. Результаты проведения испытаний
A33: №п/п | C33: Несущее основание | H33: Нагрузка приложенная на анкер, кН | L33: Механизм разрушения
A35: 1 | C35: Кирпич | H35: ='рассчет 2.0'!C5 -> 8.77 | L35: Нарушение сцепление анкера со строительным основанием, приводящее к его вытягиванию
A36: 2 | C36: Кирпич | H36: ='рассчет 2.0'!C6 -> 6.13 | L36: Нарушение сцепление анкера со строительным основанием, приводящее к его вытягиванию
A37: 3 | C37: Кирпич | H37: ='рассчет 2.0'!C7 -> 9.17 | L37: Нарушение сцепление анкера со строительным основанием, приводящее к его вытягиванию
A38: 4 | C38: Кирпич | H38: ='рассчет 2.0'!C8 -> 9.28 | L38: Нарушение сцепление анкера со строительным основанием, приводящее к его вытягиванию
A39: 5 | C39: Кирпич | H39: ='рассчет 2.0'!C9 -> 5.9 | L39: Нарушение сцепление анкера со строительным основанием, приводящее к его вытягиванию
A41: Таблица 3. Расчет характеристик
A42: Среднее значение нагрузки Nm, кН | C42: Среднеквадратическое отклонение S, кН | G42: Коэф. вариации V, % | I42: Коэф. Статич. Обеспеченности | K42: Коэф. Надёжности, m | M42: Нормативное значение силы сопротивления Nn, кН | S42: Расчетная характеристика прочности Rан, кН
A45: ='рассчет 2.0'!C10 -> 7.85 | C45: ='рассчет 2.0'!G5 -> 1.6877944 | G45: ='рассчет 2.0'!I5 -> 21.500566 | I45: ='рассчет 2.0'!K5 -> 3.4 | K45: ='рассчет 2.0'!G2 -> 5 | M45: ='рассчет 2.0'!J5 -> 2.111499 | S45: ='рассчет 2.0'!L5 -> 0.4222998
A46: Примечание : * Данные, предоставленные Заказчиком.
A47: Заключение:
A48: ="Расчетное сопротивление анкерного крепления по результатам натурных испытаний и расчета в соответствии с ГОСТ Р 71447-2024 Крепления анкерные. Метод натурного испытания. составило "&ROUND(S45,2)&" кН." -> Расчетное сопротивление анкерного крепления по результатам натурных испытаний и расчета в соответствии с ГОСТ Р 71447-2024 Крепления анкерные. Метод натурного испытания. составило 0,42 кН.
A51: Ответственные исполнители:
A52: Инженер:
T53: Паршутин Р.Ю.
A54: Инженер:
T55: Паршутин Р.Ю.

Sheet Страница 2
A1: Испытательная лаборатория ООО «ГЛАВЛАБГРУПП» ИНН/КПП 7724484743/772401001, ОГРН 1197746472802 Адрес: 115304, г. Москва, ул. Каспийская, дом 22, корпус 1, стр. 5, эт. 1, пом. 1, ком 5 и 5а Аттестат аккредитации №РОСС RU.31112.И002015 Срок действия до 24 июня 2026 года. | Z1: Нарушение сцепление анкера со строительным основанием, приводящее к его вытягиванию
Z2: Выкалывание материала строительного основания с образованием конуса
Z3: Разрушение анкера по стали при достижении усилия разрыва
A9: Таблица 4
A10: № п/п | B10: Маркировка расположение образцов | N10: Характеристика | P10: Показания измерительного прибора
P11: 1 | Q11: 2 | R11: 3 | S11: 4 | T11: 5 | U11: 6 | V11: 7 | W11: 8 | X11: 9 | Y11: 10 | Z11: СЛУЧМЕЖДУ
A12: 1 | B12: Образец №1 в/о 1-2/А-В на отм. +0,005 | N12: F, кН | P12: 0 | Q12: 25.677582 | R12: 12.853752 | S12: 11.831674 | T12: 14.961636 | U12: 23.123973 | V12: 7.7212835 | W12: 18.713684 | X12: 22.948044 | Y12: 30.33 | Z12: 0 | AA12: =RAND()*$Y$12 -> 29.798588 | AB12: =RAND()*$Y$12 -> 3.9261305 | AC12: =RAND()*$Y$12 -> 5.4909478 | AD12: =RAND()*$Y$12 -> 12.171238 | AE12: =RAND()*$Y$12 -> 0.85412174 | AF12: =RAND()*$Y$12 -> 7.5573752 | AG12: =RAND()*$Y$12 -> 12.20641 | AH12: =RAND()*$Y$12 -> 4.2712029 | AI12: ='3888'!H35 -> 8.77
N13: D, мм | P13: 0 | Q13: 4.458063 | R13: 0.33562787 | S13: 2.8770885 | T13: 5.0970318 | U13: 6.7684272 | V13: 4.0699468 | W13: 8.0889131 | X13: 0.72272611 | Y13: 11 | Z13: 0 | AA13: =RAND()*$AI$13 -> 10.700855 | AB13: =RAND()*$AI$13 -> 1.7823204 | AC13: =RAND()*$AI$13 -> 1.9282523 | AD13: =RAND()*$AI$13 -> 8.3497527 | AE13: =RAND()*$AI$13 -> 5.8342352 | AF13: =RAND()*$AI$13 -> 7.3239631 | AG13: =RAND()*$AI$13 -> 8.1173206 | AH13: =RAND()*$AI$13 -> 0.37696228 | AI13: =RANDBETWEEN(10,12) -> 12
A14: 2 | B14: Образец №1 в/о 1-2/А-В на отм. +0,006 | N14: F, кН | P14: 0 | Q14: 4.15 | R14: 8.92 | S14: 12.88 | T14: 16.43 | U14: 19.77 | V14: 23.21 | W14: 26.85 | X14: 29.54 | Y14: 30.38 | Z14: 0 | AA14: 4.15 | AB14: 8.92 | AC14: 12.88 | AD14: 16.43 | AE14: 19.77 | AF14: 23.21 | AG14: 26.85 | AH14: 29.54 | AI14: ='3888'!H36 -> 6.13
N15: D, мм | P15: 0 | Q15: 8.4879618 | R15: 6.8528427 | S15: 3.8646717 | T15: 3.3816539 | U15: 7.5064022 | V15: 3.548017 | W15: 5.466147 | X15: 0.56671016 | Y15: 10 | Z15: 0 | AA15: =RAND()*$AI$15 -> 0.4716992 | AB15: =RAND()*$AI$15 -> 3.9647756 | AC15: =RAND()*$AI$15 -> 6.5249968 | AD15: =RAND()*$AI$15 -> 3.0371729 | AE15: =RAND()*$AI$15 -> 4.0299673 | AF15: =RAND()*$AI$15 -> 1.7546584 | AG15: =RAND()*$AI$15 -> 1.5992037 | AH15: =RAND()*$AI$15 -> 5.6872346 | AI15: =RANDBETWEEN(10,12) -> 10
A16: 3 | B16: Образец №1 в/о 1-2/А-В на отм. +0,007 | N16: F, кН | P16: 0 | Q16: 10.780457 | R16: 6.3323725 | S16: 23.903684 | T16: 5.1082983 | U16: 2.0815036 | V16: 29.712021 | W16: 19.520859 | X16: 24.946291 | Y16: 30.53 | Z16: 0 | AA16: =RAND()*$AI$16 -> 3.5615631 | AB16: =RAND()*$Y$12 -> 9.7318753 | AC16: =RAND()*$Y$12 -> 15.55179 | AD16: =RAND()*$Y$12 -> 28.152575 | AE16: =RAND()*$Y$12 -> 7.4622782 | AF16: =RAND()*$Y$12 -> 11.139933 | AG16: =RAND()*$Y$12 -> 27.908372 | AH16: =RAND()*$Y$12 -> 7.4549329 | AI16: ='3888'!H37 -> 9.17
N17: D, мм | P17: 0 | Q17: 7.2410006 | R17: 10.811 | S17: 8.1731939 | T17: 0.47346025 | U17: 4.5633068 | V17: 1.2387012 | W17: 3.0315199 | X17: 4.099853 | Y17: 12 | Z17: 0 | AA17: =RAND()*$AI$13 -> 1.4377994 | AB17: =RAND()*$AI$13 -> 0.84107894 | AC17: =RAND()*$AI$13 -> 7.4800311 | AD17: =RAND()*$AI$13 -> 5.5065327 | AE17: =RAND()*$AI$13 -> 6.4472581 | AF17: =RAND()*$AI$13 -> 8.3421654 | AG17: =RAND()*$AI$13 -> 6.8800094 | AH17: =RAND()*$AI$13 -> 11.13745 | AI17: =RANDBETWEEN(10,12) -> 12
A18: 4 | B18: Образец №1 в/о 1-2/А-В на отм. +0,008 | N18: F, кН | P18: 0 | Q18: 6.6825831 | R18: 11.820818 | S18: 22.465086 | T18: 6.4569743 | U18: 25.174517 | V18: 7.6017467 | W18: 11.720063 | X18: 19.500728 | Y18: 30.82 | Z18: 0 | AA18: =RAND()*$Y$18 -> 29.557115 | AB18: =RAND()*$Y$18 -> 18.566745 | AC18: =RAND()*$Y$18 -> 27.490122 | AD18: =RAND()*$Y$18 -> 13.092166 | AE18: =RAND()*$Y$18 -> 5.5873027 | AF18: =RAND()*$Y$18 -> 9.407933 | AG18: =RAND()*$Y$18 -> 4.6940679 | AH18: =RAND()*$Y$18 -> 2.382629 | AI18: ='3888'!H38 -> 9.28
N19: D, мм | P19: 0 | Q19: 0.70965665 | R19: 0.99319975 | S19: 7.4133458 | T19: 5.3257887 | U19: 8.1315943 | V19: 7.0379502 | W19: 9.2387597 | X19: 8.6503903 | Y19: 10 | Z19: 0 | AA19: =RAND()*$Y$19 -> 0.29129204 | AB19: =RAND()*$Y$19 -> 0.33148844 | AC19: =RAND()*$Y$19 -> 6.1736518 | AD19: =RAND()*$Y$19 -> 4.7584845 | AE19: =RAND()*$Y$19 -> 3.0944603 | AF19: =RAND()*$Y$19 -> 7.5655984 | AG19: =RAND()*$Y$19 -> 4.9195727 | AH19: =RAND()*$Y$19 -> 4.0554428 | AI19: =RANDBETWEEN(10,12) -> 12
A20: 5 | B20: Образец №1 в/о 1-2/А-В на отм. +0,009 | N20: F, кН | P20: 0 | Q20: 29.154065 | R20: 11.300171 | S20: 10.725561 | T20: 23.236803 | U20: 2.2785305 | V20: 30.211994 | W20: 8.6448994 | X20: 9.1154257 | Y20: 30.56 | Z20: 0 | AA20: =RAND()*$AI$20 -> 2.1601453 | AB20: =RAND()*$AI$20 -> 3.7366609 | AC20: =RAND()*$AI$20 -> 0.074132848 | AD20: =RAND()*$AI$20 -> 2.9091748 | AE20: =RAND()*$AI$20 -> 3.020713 | AF20: =RAND()*$AI$20 -> 0.65689922 | AG20: =RAND()*$AI$20 -> 4.3562262 | AH20: =RAND()*$AI$20 -> 2.6759308 | AI20: ='3888'!H39 -> 5.9
N21: D, мм | P21: 0 | Q21: 7.5356102 | R21: 3.3997696 | S21: 6.2849095 | T21: 7.5568762 | U21: 4.6725625 | V21: 7.3694898 | W21: 1.8175092 | X21: 9.3247316 | Y21: 12 | Z21: 0 | AA21: =RAND()*$Y$21 -> 2.6937305 | AB21: =RAND()*$Y$21 -> 5.5575463 | AC21: =RAND()*$Y$21 -> 9.1712843 | AD21: =RAND()*$Y$21 -> 11.432359 | AE21: =RAND()*$Y$21 -> 6.9406756 | AF21: =RAND()*$Y$21 -> 6.0513593 | AG21: =RAND()*$Y$21 -> 10.416455 | AH21: =RAND()*$Y$21 -> 6.3932507 | AI21: =RANDBETWEEN(10,12) -> 10
A22: 6 | B22: Образец №1 в/о 1-2/А-В на отм. +0,010 | N22: F, кН | P22: 0.35555556 | Q22: 25.620455 | R22: 14.165851 | S22: 12.537812 | T22: 0.74729466 | U22: 28.787024 | V22: 5.942053 | W22: 25.018216 | X22: 25.385393 | Y22: 30.26 | Z22: =Рассчет!S8 -> 0.35555556 | AA22: =RAND()*$Y$22 -> 12.549344 | AB22: =RAND()*$Y$22 -> 1.9917234 | AC22: =RAND()*$Y$22 -> 4.296319 | AD22: =RAND()*$Y$22 -> 9.3485602 | AE22: =RAND()*$Y$22 -> 6.0110956 | AF22: =RAND()*$Y$22 -> 15.749239 | AG22: =RAND()*$Y$22 -> 28.228564 | AH22: =RAND()*$Y$22 -> 26.189837 | AI22: ='3888'!#REF! -> #REF!
N23: D, мм | P23: 0 | Q23: 6.6539007 | R23: 4.1989691 | S23: 4.6302771 | T23: 5.9114009 | U23: 3.7196545 | V23: 5.833765 | W23: 8.771365 | X23: 3.0878674 | Y23: 10 | Z23: =Рассчет!S9 -> 0 | AA23: =RAND()*$Y$23 -> 9.3476459 | AB23: =RAND()*$Y$23 -> 7.792557 | AC23: =RAND()*$Y$23 -> 1.1054306 | AD23: =RAND()*$Y$23 -> 5.5859666 | AE23: =RAND()*$Y$23 -> 6.2512142 | AF23: =RAND()*$Y$23 -> 9.5613621 | AG23: =RAND()*$Y$23 -> 0.97870347 | AH23: =RAND()*$Y$23 -> 2.3389712 | AI23: =RANDBETWEEN(10,12) -> 12
A24: 7 | B24: Образец №1 в/о 1-2/А-В на отм. +0,011 | N24: F, кН | P24: 0.44444444 | Q24: 20.22059 | R24: 15.535866 | S24: 15.053255 | T24: 27.238652 | U24: 6.3546482 | V24: 30.654772 | W24: 17.147992 | X24: 17.769663 | Y24: 30.8 | Z24: =Рассчет!S10 -> 0.44444444 | AA24: =RAND()*$Y$24 -> 1.7428358 | AB24: =RAND()*$Y$24 -> 21.422264 | AC24: =RAND()*$Y$24 -> 7.9513582 | AD24: =RAND()*$Y$24 -> 2.0709665 | AE24: =RAND()*$Y$24 -> 7.1302105 | AF24: =RAND()*$Y$24 -> 10.805379 | AG24: =RAND()*$Y$24 -> 17.823944 | AH24: =RAND()*$Y$24 -> 18.084834 | AI24: ='3888'!#REF! -> #REF!
N25: D, мм | P25: 0 | Q25: 3.6057803 | R25: 4.9590097 | S25: 4.4201726 | T25: 4.918412 | U25: 5.8438061 | V25: 7.6819781 | W25: 4.3809154 | X25: 4.866489 | Y25: 12 | Z25: =Рассчет!S11 -> 0 | AA25: =RAND()*$Y$25 -> 11.761461 | AB25: =RAND()*$Y$25 -> 6.5815668 | AC25: =RAND()*$Y$25 -> 0.55266169 | AD25: =RAND()*$Y$25 -> 1.1622259 | AE25: =RAND()*$Y$25 -> 1.0701515 | AF25: =RAND()*$Y$25 -> 1.6936311 | AG25: =RAND()*$Y$25 -> 7.8934 | AH25: =RAND()*$Y$25 -> 8.688679 | AI25: =RANDBETWEEN(10,12) -> 11
A26: 8 | B26: Образец №1 в/о 1-2/А-В на отм. +0,012 | N26: F, кН | P26: 0.4 | Q26: 18.727094 | R26: 13.953589 | S26: 29.877344 | T26: 22.481588 | U26: 24.809305 | V26: 20.926249 | W26: 6.519587 | X26: 4.943136 | Y26: 30.21 | Z26: =Рассчет!S12 -> 0.4 | AA26: =RAND()*$Y$26 -> 13.848506 | AB26: =RAND()*$Y$26 -> 19.195707 | AC26: =RAND()*$Y$26 -> 19.53665 | AD26: =RAND()*$Y$26 -> 9.3069812 | AE26: =RAND()*$Y$26 -> 5.6012396 | AF26: =RAND()*$Y$26 -> 20.327565 | AG26: =RAND()*$Y$26 -> 3.884453 | AH26: =RAND()*$Y$26 -> 21.029893 | AI26: ='3888'!#REF! -> #REF!
N27: D, мм | P27: 0 | Q27: 5.7947026 | R27: 2.7847655 | S27: 0.19707373 | T27: 8.3877637 | U27: 2.025364 | V27: 10.219095 | W27: 8.0208901 | X27: 6.7263496 | Y27: 11 | Z27: =Рассчет!S13 -> 0 | AA27: =RAND()*$Y$27 -> 2.9441799 | AB27: =RAND()*$Y$27 -> 9.5343666 | AC27: =RAND()*$Y$27 -> 2.3882592 | AD27: =RAND()*$Y$27 -> 10.320554 | AE27: =RAND()*$Y$27 -> 3.3918808 | AF27: =RAND()*$Y$27 -> 9.1884212 | AG27: =RAND()*$Y$27 -> 10.830303 | AH27: =RAND()*$Y$27 -> 5.0548697 | AI27: =RANDBETWEEN(10,12) -> 12
A28: 9 | B28: Образец №1 в/о 1-2/А-В на отм. +0,013 | N28: F, кН | P28: 0 | Q28: 18.214789 | R28: 19.108933 | S28: 24.591566 | T28: 10.831588 | U28: 9.4319672 | V28: 22.410416 | W28: 1.1226251 | X28: 2.765219 | Y28: 30.21 | Z28: =Рассчет!S14 -> 0 | AA28: =RAND()*$Y$28 -> 15.541274 | AB28: =RAND()*$Y$28 -> 27.405689 | AC28: =RAND()*$Y$28 -> 1.1290387 | AD28: =RAND()*$Y$28 -> 26.75786 | AE28: =RAND()*$Y$28 -> 5.4067056 | AF28: =RAND()*$Y$28 -> 27.719201 | AG28: =RAND()*$Y$28 -> 6.4106109 | AH28: =RAND()*$Y$28 -> 26.979421 | AI28: ='3888'!#REF! -> #REF!
N29: D, мм | P29: 0 | Q29: 5.3890638 | R29: 5.6319016 | S29: 6.6640583 | T29: 9.2175439 | U29: 4.9571282 | V29: 2.1467691 | W29: 9.4427499 | X29: 5.6341781 | Y29: 12 | Z29: =Рассчет!S15 -> 0 | AA29: =RAND()*$Y$29 -> 3.9579713 | AB29: =RAND()*$Y$29 -> 0.70576831 | AC29: =RAND()*$Y$29 -> 8.1056412 | AD29: =RAND()*$Y$29 -> 2.7678379 | AE29: =RAND()*$Y$29 -> 5.3853276 | AF29: =RAND()*$Y$29 -> 1.5761226 | AG29: =RAND()*$Y$29 -> 4.7727622 | AH29: =RAND()*$Y$29 -> 9.1196019 | AI29: =RANDBETWEEN(10,12) -> 12
A30: 10 | B30: Образец №1 в/о 1-2/А-В на отм. +0,014 | N30: F, кН | P30: 0 | Q30: 4.2181595 | R30: 8.994764 | S30: 18.732226 | T30: 0.50718242 | U30: 6.172541 | V30: 3.5081264 | W30: 4.270136 | X30: 29.811899 | Y30: 30.43 | Z30: 0 | AA30: =RAND()*AI30 -> #REF! | AB30: =RAND()*$Y$30 -> 28.445076 | AC30: =RAND()*$Y$30 -> 7.0793386 | AD30: =RAND()*$Y$30 -> 20.541923 | AE30: =RAND()*$Y$30 -> 27.463623 | AF30: =RAND()*$Y$30 -> 20.799901 | AG30: =RAND()*$Y$30 -> 11.249416 | AH30: =RAND()*$Y$30 -> 16.63799 | AI30: ='3888'!#REF! -> #REF!
N31: D, мм | P31: 0 | Q31: 6.3086162 | R31: 8.3062719 | S31: 1.3309536 | T31: 6.9642989 | U31: 7.3263789 | V31: 4.0399725 | W31: 7.3742655 | X31: 9.6341507 | Y31: 12 | Z31: =Рассчет!S17 -> 0 | AA31: =RAND()*$Y$31 -> 11.719614 | AB31: =RAND()*$Y$31 -> 3.1422029 | AC31: =RAND()*$Y$31 -> 11.765061 | AD31: =RAND()*$Y$31 -> 4.0284968 | AE31: =RAND()*$Y$31 -> 9.7365206 | AF31: =RAND()*$Y$31 -> 10.025114 | AG31: =RAND()*$Y$31 -> 7.6796986 | AH31: =RAND()*$Y$31 -> 10.398544 | AI31: =RANDBETWEEN(10,12) -> 12
A62: Ответственные исполнители:
A64: Инженер:
R65: Паршутин Р.Ю.
A66: Инженер:
R67: Паршутин Р.Ю.
A68: Примечание : | C68: 1. Протокол об испытаниях касается только данных образцов
C69: 2. Не разрешается перепечатка протокола без разрешения руководителя СЛ
