Workbook

Sheet Рассчеты (3)
A10: Протокол об испытаниях №0000.ВС/04.24 от 01.04.2024
A11: Анкеры механические для крепления в бетоне по ГОСТ 56731-2023
A13: Основание для проведения работ: | D13: СЧЕТ № 23305/14-11-25/2 от 14 ноября 2025 года
A14: Заказчик :
A15: Наименование объекта:
A16: Адрес объекта:
A17: Дата испытаний
A18: Вид испытаний: | D18: Испытание на вырыв
A19: Методика проведения испытаний: | D19: ГОСТ 56731-2023 Анкера механические для крепления в бетоне. Методы испытаний
A20: СТО-44416204-010-2010 «Крепления анкерные. Метод определения несущей способности по результатам натурных испытаний»
A21: Оборудование, инструменты: | D21: Измеритель адгезии ПСО-100МГ4АД зав. 2573, свидетельство о поверке «ВИК-НДТ», зав. №3581, свидетельство о калибровке № К0034-1001/24 действительно до 09.01.2025;
A22: № С-ГА/24-06-2025/444021486 действительно до 23.06.2027; Измеритель параметров микроклимата; Метеоскоп-М; "МЕТЕОСКОП-М"; Рег. № 32014-11 зав. № 615022, свидетельство о поверке №С-ДЮП/05-07-2024/353605602 действительно до 04.07.2026. Перфоратор DeWALT, рулетка, молоток.
A25: Описание и тип анкера, наименование изготовителя: | D25: Дюбель для теплоизоляции 10х180мм ИЗТ, с металлическим стержнем и термоголовкой - ООО "HILTI"
A26: Таблица 1
A27: Дата изготовления | B27: Место проведения | D27: Материал | E27: Метод сверления | F27: t, ℃ | G27: Глубина заделки, мм | H27: Расстояние между анкерами, мм | I27: Описание и тип анкера, наименование изготовителя: | N27: Случмежду
A28: 46059 | B28: Стена в/о 1-2/А-Б на отм. +1,050 | D28: Тяжелый бетон В25 | E28: Бурение | F28: 15 | G28: 36 | H28: 300 | I28: Анкер-Ш 10х180мм ИЗТ, с металлическим стержнем и термоголовкой - ООО "HILTI" | N28: =RANDBETWEEN(450,500)/10 -> 50
B30: № образца в серии
A31: № испытания | B31: Анкер-Ш 10х180мм | C31: Анкер-Ш 12х180мм
A32: 1 | B32: =RANDBETWEEN(450,500)/10 -> 48 | L32: 1 | M32: нарушение контакта анкера с бетоном | T32: Нагрузка
A33: 2 | B33: =RANDBETWEEN(450,500)/10 -> 45.4 | L33: 2 | M33: выкалывание бетона основания | T33: 1
A34: 3 | B34: =RANDBETWEEN(450,500)/10 -> 48.7 | L34: 3 | M34: разрушение анкера по стали | T34: 2
A35: 4 | B35: =RANDBETWEEN(450,500)/10 -> 48.6 | T35: 3
A36: 5 | B36: =RANDBETWEEN(450,500)/10 -> 47.4 | T36: 4
A37: 6 | B37: =RANDBETWEEN(450,500)/10 -> 46.6 | L37: 1 | M37: нарушение контакта анкера с бетоном | T37: 5
A38: 7 | B38: =RANDBETWEEN(450,500)/10 -> 48.9 | L38: 2 | M38: выкалывание бетона основания | T38: 6
A39: 8 | B39: =RANDBETWEEN(450,500)/10 -> 46.8 | L39: 3 | M39: разрушение анкера по стали | T39: 7
A40: 9 | B40: =RANDBETWEEN(450,500)/10 -> 49.2 | T40: 8
A41: 10 | B41: =RANDBETWEEN(450,500)/10 -> 46.8 | T41: 9
L42: 1 | M42: нарушение контакта анкера с бетоном | T42: 10
A43: Таблица 3 | T43: 15
A44: Среднее значение нагрузки N, кН: | C44: Среднеквадратическое отклонение S, кН: | E44: Коэф. вариации v, %: | F44: Коэф., К: | G44: Коэф. надёжности, m: | H44: Коэф. условий работы: | I44: Расч сопротивление | J44: Расчётное сопротивление с учетом коэффициента условий работы:
A45: 1 | C45: 2 | E45: 3 | F45: 4 | G45: 5 | H45: 6 | I45: 7
A46: =AVERAGE(B32:B41) -> 47.64 | C46: =1/A46*SQRT((B32-A46)^2/MAX(A32:A41)-1) -> #NUM!
A49: Коэффициент надёжности по материалу, m:
A50: Коэффициент условий работы:
A51: Расчётное сопротивление анкерного крепления:
A52: Расчётное сопротивление анкерного крепления с учетом коэффициента условий работы:
A53: Заведующий строительной лабораторией: | G53: _________________/Симоров А.Ю./
A55: Ответственные исполнители:
A57: Инженер: | G57: _________________/Симоров А.Ю./
...

Sheet Лестницы, ограждения
A1: Испытательная лаборатория ООО «ГЛАВЛАБГРУПП» ИНН/КПП 7724484743/772401001, ОГРН 1197746472802 Адрес: 115304, г. Москва, ул. Каспийская, дом 22, корпус 1, стр. 5, эт. 1, пом. 1, ком 5 и 5а Аттестат аккредитации №РОСС RU.31112.И002015 Срок действия до 24 июня 2026 года.
AA2: Точки крепления к стене пишем в 2 раза меньше (как кол-во испытаний балок)
R9: УТВЕРЖДАЮ:
R10: Заведующий строительной лабораторией: | AE10: кн | AF10: кгс
W11: Симоров А.Ю. | AB11: Балки крепления (двойные) | AE11: =ROUND((AE12*120)/(2.5*AC24)*1.5/100,2) -> 3.24 | AF11: =AE11*100 -> 324
R12: (подпись) | AB12: Высота лестницы | AE12: 18 | AF12: -
R13: =TEXT($G$23,"[$-FC19]«ДД» ММММ ГГГГ \г.") -> «05» февраля 2026 г.
A14: ="Протокол №"&MID(CELL("filename",A1),SEARCH("]",CELL("filename"))+1,255)&".ЭИ от "&TEXT($G$23,"ДД.ММ.ГГГГ")&"" -> Протокол №Лестницы, ограждения.ЭИ от 05.02.2026
A16: Заказчик : | G16: ООО «АТЛАНТ»
A17: Исполнитель: | G17: ООО «ГЛАВЛАБГРУПП»
A18: Наименование объекта: | G18: Квартал Издание. «Комплекс жилых домов переменной этажности со встроенно-пристроенными помещениями общественного назначения и подземной автостоянкой»
A20: Адрес объекта: | G20: г. Москва, внутригородское образование Нижегородское, шоссе Перовское, земельный участок с кадастровым номером 77:04:0002001:8601
A22: Вид контроля: | G22: Испытания лестниц и ограждений на прочность | AB22: ширина | AC22: 0.5 | AE22: кн | AF22: кгс
A23: Дата проведения испытаний: | G23: 46058 | AB23: длина | AC23: 0.5 | AE23: =(((AC22*AC23)*1.2)/(0.5*AC24))*1.5 -> 0.225 | AF23: =AE23*100 -> 22.5
A24: Методика испытаний: | G24: ГОСТ Р 53254-2009 "Техника пожарная. Лестницы пожарные наружные стационарные. Ограждения кровли. Общие технические требования. Методы испытаний" | AB24: количество балок | AC24: 4
A26: Используемое оборудование: | G26: Динамометр АЦД/1Р-100/7И-2, зав. №5660, свидетельство о поверке № С-БЕ/13-05-2025/432045473, действительно до 12.05.2026; Комплект для визуального контроля типа ВИК, зав. №3579, свидетельство о калибровке № К0063-0901/25, действительно до 08.01.2026.
A30: Условия проведения испытаний: | G30: ="+20°C" -> +20°C
A31: Результаты испытаний:
A32: №п/п | C32: Наименование испытываемого элемента | K32: № точки | O32: Нагрузка, кН(кгс) | W32: Результаты испытаний
A34: 1 | C34: 2 | K34: 3 | O34: 4 | W34: 5
A35: Пожарная лестница в/о 1-2/Д-Е с отм. +12,200 до отм. +14,990
A36: 1 | C36: Ступени | K36: 1 | O36: 1.8 | S36: ="(180)" -> (180) | W36: без отклонений
K37: 2 | O37: 1.8 | S37: ="(180)" -> (180) | W37: без отклонений
K38: 3 | O38: 1.8 | S38: ="(180)" -> (180) | W38: без отклонений
K39: 4 | O39: 1.8 | S39: ="(180)" -> (180) | W39: без отклонений
A40: 2 | C40: Балки | K40: 1 | O40: =$AE$11 -> 3.24 | S40: ="("&($AF$11)&")" -> (324) | W40: без отклонений
K41: 2 | O41: =$AE$11 -> 3.24 | S41: ="("&($AF$11)&")" -> (324) | W41: без отклонений
K42: 3 | O42: =$AE$11 -> 3.24 | S42: ="("&($AF$11)&")" -> (324) | W42: без отклонений
K43: 4 | O43: =$AE$11 -> 3.24 | S43: ="("&($AF$11)&")" -> (324) | W43: без отклонений
A44: 3 | C44: Ограждения лестницы | K44: 1 | O44: 0.54 | S44: ="(54)" -> (54) | W44: без отклонений
K45: 2 | O45: 0.54 | S45: ="(54)" -> (54) | W45: без отклонений
K46: 3 | O46: 0.54 | S46: ="(54)" -> (54) | W46: без отклонений
K47: 4 | O47: 0.54 | S47: ="(54)" -> (54) | W47: без отклонений
A48: 4 | C48: Площадка | K48: 1 | O48: =$AE$23 -> 0.225 | S48: ="("&($AF$23)&")" -> (22,5) | W48: без отклонений
K49: 2 | O49: =$AE$23 -> 0.225 | S49: ="("&($AF$23)&")" -> (22,5) | W49: без отклонений
K50: 3 | O50: =$AE$23 -> 0.225 | S50: ="("&($AF$23)&")" -> (22,5) | W50: без отклонений
K51: 4 | O51: =$AE$23 -> 0.225 | S51: ="("&($AF$23)&")" -> (22,5) | W51: без отклонений
A52: Ограждение кровли в/о 2-7/Г-Е на отм. +14,730
A53: 5 | C53: Ограждения кровли | K53: 1 | O53: 0.54 | S53: ="(54)" -> (54) | W53: без отклонений
K54: 2 | O54: 0.54 | S54: ="(54)" -> (54) | W54: без отклонений
...

Sheet Бирки
A6: Наименование конструкции: | C6: ='Лестницы, ограждения'!C36 -> Ступени | E6: Наименование конструкции: | G6: ='Лестницы, ограждения'!C36 -> Ступени
A7: Дата проведения испытаний: | C7: ='Лестницы, ограждения'!G23 -> 46058 | E7: Дата проведения испытаний: | G7: =C7 -> 46058
A8: Нагрузка, кН (кгс): | C8: ='Лестницы, ограждения'!O36 -> 1.8 | E8: Нагрузка, кН (кгс): | G8: ='Лестницы, ограждения'!O36 -> 1.8
A14: Наименование конструкции: | C14: ='Лестницы, ограждения'!C36 -> Ступени | E14: Наименование конструкции: | G14: ='Лестницы, ограждения'!C36 -> Ступени
A15: Дата проведения испытаний: | C15: =C7 -> 46058 | E15: Дата проведения испытаний: | G15: =C7 -> 46058
A16: Нагрузка, кН (кгс): | C16: ='Лестницы, ограждения'!O36 -> 1.8 | E16: Нагрузка, кН (кгс): | G16: ='Лестницы, ограждения'!O36 -> 1.8
A22: Наименование конструкции: | C22: =#REF! -> #REF! | E22: Наименование конструкции: | G22: =#REF! -> #REF!
A23: Дата проведения испытаний: | C23: =C7 -> 46058 | E23: Дата проведения испытаний: | G23: =C7 -> 46058
A24: Нагрузка, кН (кгс): | C24: ='Лестницы, ограждения'!O40 -> 3.24 | E24: Нагрузка, кН (кгс): | G24: ='Лестницы, ограждения'!O40 -> 3.24
A30: Наименование конструкции: | C30: =#REF! -> #REF! | E30: Наименование конструкции: | G30: =#REF! -> #REF!
A31: Дата проведения испытаний: | C31: =C7 -> 46058 | E31: Дата проведения испытаний: | G31: =C7 -> 46058
A32: Нагрузка, кН (кгс): | C32: ='Лестницы, ограждения'!O40 -> 3.24 | E32: Нагрузка, кН (кгс): | G32: ='Лестницы, ограждения'!O40 -> 3.24
A38: Наименование конструкции: | C38: =#REF! -> #REF! | E38: Наименование конструкции: | G38: =#REF! -> #REF!
A39: Дата проведения испытаний: | C39: =C7 -> 46058 | E39: Дата проведения испытаний: | G39: =C7 -> 46058
A40: Нагрузка, кН (кгс): | C40: ='Лестницы, ограждения'!O48 -> 0.225 | E40: Нагрузка, кН (кгс): | G40: ='Лестницы, ограждения'!O48 -> 0.225
A46: Наименование конструкции: | C46: =#REF! -> #REF! | E46: Наименование конструкции: | G46: =#REF! -> #REF!
A47: Дата проведения испытаний: | C47: =C7 -> 46058 | E47: Дата проведения испытаний: | G47: =C7 -> 46058
A48: Нагрузка, кН (кгс): | C48: ='Лестницы, ограждения'!O48 -> 0.225 | E48: Нагрузка, кН (кгс): | G48: ='Лестницы, ограждения'!O48 -> 0.225
A54: Наименование конструкции: | C54: =#REF! -> #REF! | E54: Наименование конструкции: | G54: =#REF! -> #REF!
A55: Дата проведения испытаний: | C55: =C7 -> 46058 | E55: Дата проведения испытаний: | G55: =C7 -> 46058
A56: Нагрузка, кН (кгс): | C56: =#REF! -> #REF! | E56: Нагрузка, кН (кгс): | G56: =#REF! -> #REF!
A62: Наименование конструкции: | C62: =#REF! -> #REF! | E62: Наименование конструкции: | G62: =#REF! -> #REF!
A63: Дата проведения испытаний: | C63: =C7 -> 46058 | E63: Дата проведения испытаний: | G63: =C7 -> 46058
A64: Нагрузка, кН (кгс): | C64: =#REF! -> #REF! | E64: Нагрузка, кН (кгс): | G64: =#REF! -> #REF!
A70: Наименование конструкции: | C70: =#REF! -> #REF! | E70: Наименование конструкции: | G70: =#REF! -> #REF!
A71: Дата проведения испытаний: | C71: =C7 -> 46058 | E71: Дата проведения испытаний: | G71: =C7 -> 46058
A72: Нагрузка, кН (кгс): | C72: =#REF! -> #REF! | E72: Нагрузка, кН (кгс): | G72: =#REF! -> #REF!
A78: Наименование конструкции: | C78: =#REF! -> #REF! | E78: Наименование конструкции: | G78: =#REF! -> #REF!
A79: Дата проведения испытаний: | C79: =C7 -> 46058 | E79: Дата проведения испытаний: | G79: =C7 -> 46058
A80: Нагрузка, кН (кгс): | C80: =#REF! -> #REF! | E80: Нагрузка, кН (кгс): | G80: =#REF! -> #REF!
